
[2025-08-14 10:16:38] Terjadi error:
Traceback (most recent call last):
  File "c:\Users\DELL\Desktop\ReportApp\workflows\file_ops.py", line 224, in refresh_excel_workbooks
    wb = excel.Workbooks.Open(str(excel_file))
  File "C:\Users\DELL\AppData\Local\Programs\Python\Python313\Lib\site-packages\win32com\gen_py\00020813-0000-0000-C000-000000000046x0x1x9.py", line 41293, in Open
    ret = self._oleobj_.InvokeTypes(1923, LCID, 1, (13, 0), ((8, 1), (12, 17), (12, 17), (12, 17), (12, 17), (12, 17), (12, 17), (12, 17), (12, 17), (12, 17), (12, 17), (12, 17), (12, 17), (12, 17), (12, 17)),Filename
    	, UpdateLinks, ReadOnly, Format, Password, WriteResPassword
    	, IgnoreReadOnlyRecommended, Origin, Delimiter, Editable, Notify
    	, Converter, AddToMru, Local, CorruptLoad)
pywintypes.com_error: (-2147023170, 'The remote procedure call failed.', None, None)

During handling of the above exception, another exception occurred:

Traceback (most recent call last):
  File "c:\Users\DELL\Desktop\ReportApp\main.py", line 127, in <module>
    main()
    ~~~~^^
  File "c:\Users\DELL\Desktop\ReportApp\main.py", line 63, in main
    process_danamon_report(tracker, task_paths)
    ~~~~~~~~~~~~~~~~~~~~~~^^^^^^^^^^^^^^^^^^^^^
  File "c:\Users\DELL\Desktop\ReportApp\workflows\danamon_ops.py", line 315, in process_danamon_report
    refresh_excel_workbooks(["d:\\RYAN\\2. Queries\\Query Danamon.xlsx", os_path, pickup_path])
    ~~~~~~~~~~~~~~~~~~~~~~~^^^^^^^^^^^^^^^^^^^^^^^^^^^^^^^^^^^^^^^^^^^^^^^^^^^^^^^^^^^^^^^^^^^^
  File "c:\Users\DELL\Desktop\ReportApp\workflows\file_ops.py", line 239, in refresh_excel_workbooks
    excel.Quit()
    ~~~~~~~~~~^^
  File "C:\Users\DELL\AppData\Local\Programs\Python\Python313\Lib\site-packages\win32com\gen_py\00020813-0000-0000-C000-000000000046x0x1x9.py", line 44738, in Quit
    return self._oleobj_.InvokeTypes(302, LCID, 1, (24, 0), (),)
           ~~~~~~~~~~~~~~~~~~~~~~~~~^^^^^^^^^^^^^^^^^^^^^^^^^^^^
pywintypes.com_error: (-2147023174, 'The RPC server is unavailable.', None, None)
